[2024-11-10T00:05:44.533+0000] {taskinstance.py:1083} INFO - Dependencies all met for <TaskInstance: dag_run1.tsk2 manual__2024-11-10T00:05:37.687877+00:00 [queued]>
[2024-11-10T00:05:44.539+0000] {taskinstance.py:1083} INFO - Dependencies all met for <TaskInstance: dag_run1.tsk2 manual__2024-11-10T00:05:37.687877+00:00 [queued]>
[2024-11-10T00:05:44.539+0000] {taskinstance.py:1279} INFO - 
--------------------------------------------------------------------------------
[2024-11-10T00:05:44.539+0000] {taskinstance.py:1280} INFO - Starting attempt 1 of 1
[2024-11-10T00:05:44.539+0000] {taskinstance.py:1281} INFO - 
--------------------------------------------------------------------------------
[2024-11-10T00:05:44.546+0000] {taskinstance.py:1300} INFO - Executing <Task(TriggerDagRunOperator): tsk2> on 2024-11-10 00:05:37.687877+00:00
[2024-11-10T00:05:44.549+0000] {standard_task_runner.py:55} INFO - Started process 16755 to run task
[2024-11-10T00:05:44.553+0000] {standard_task_runner.py:82} INFO - Running: ['***', 'tasks', 'run', 'dag_run1', 'tsk2', 'manual__2024-11-10T00:05:37.687877+00:00', '--job-id', '123', '--raw', '--subdir', 'DAGS_FOLDER/dag_run1.py', '--cfg-path', '/tmp/tmp4tpmnqmx']
[2024-11-10T00:05:44.554+0000] {standard_task_runner.py:83} INFO - Job 123: Subtask tsk2
[2024-11-10T00:05:44.601+0000] {task_command.py:388} INFO - Running <TaskInstance: dag_run1.tsk2 manual__2024-11-10T00:05:37.687877+00:00 [running]> on host a8ff7d7dd89a
[2024-11-10T00:05:44.660+0000] {taskinstance.py:1509} INFO - Exporting the following env vars:
AIRFLOW_CTX_DAG_OWNER=***
AIRFLOW_CTX_DAG_ID=dag_run1
AIRFLOW_CTX_TASK_ID=tsk2
AIRFLOW_CTX_EXECUTION_DATE=2024-11-10T00:05:37.687877+00:00
AIRFLOW_CTX_TRY_NUMBER=1
AIRFLOW_CTX_DAG_RUN_ID=manual__2024-11-10T00:05:37.687877+00:00
[2024-11-10T00:05:44.680+0000] {taskinstance.py:1768} ERROR - Task failed with exception
Traceback (most recent call last):
  File "/home/airflow/.local/lib/python3.7/site-packages/airflow/operators/trigger_dagrun.py", line 144, in execute
    replace_microseconds=False,
  File "/home/airflow/.local/lib/python3.7/site-packages/airflow/api/common/trigger_dag.py", line 128, in trigger_dag
    replace_microseconds=replace_microseconds,
  File "/home/airflow/.local/lib/python3.7/site-packages/airflow/api/common/trigger_dag.py", line 52, in _trigger_dag
    raise DagNotFound(f"Dag id {dag_id} not found")
airflow.exceptions.DagNotFound: Dag id dag_run2 not found
[2024-11-10T00:05:44.684+0000] {taskinstance.py:1323} INFO - Marking task as FAILED. dag_id=dag_run1, task_id=tsk2, execution_date=20241110T000537, start_date=20241110T000544, end_date=20241110T000544
[2024-11-10T00:05:44.692+0000] {standard_task_runner.py:105} ERROR - Failed to execute job 123 for task tsk2 (Dag id dag_run2 not found; 16755)
[2024-11-10T00:05:44.734+0000] {local_task_job.py:208} INFO - Task exited with return code 1
[2024-11-10T00:05:44.748+0000] {taskinstance.py:2578} INFO - 0 downstream tasks scheduled from follow-on schedule check
